<?xml version="1.0" ?>

<robot name="robot">

    <gazebo>
        <plugin filename="libgazebo_ros_diff_drive.so" name="differential_drive_controller">
            <alwaysOn>true</alwaysOn>
            <updateRate>20</updateRate>
            <leftJoint>joint_chassis_left_wheel</leftJoint>
            <rightJoint>joint_chassis_right_wheel</rightJoint>
            <wheelSeparation>0.4</wheelSeparation>
            <wheelDiameter>0.05</wheelDiameter>
            <torque>10</torque>
            <commandTopic>cmd_vel</commandTopic>
            <odometryTopic>odom</odometryTopic>
            <odometryFrame>odom</odometryFrame>
            <robotBaseFrame>base_link</robotBaseFrame>
        </plugin>
    </gazebo>

    <gazebo reference="base_link">
        <material>Gazebo/Black</material>
    </gazebo>

    <link name="base_link">
        <inertial>
            <mass value="25" />
            <origin xyz="0 0 0.3" rpy="0 0 0" />
            <inertia ixx="0.578125" ixy="0" ixz="0" iyy="0.578125" iyz="0" izz="0.78125" />
        </inertial>

        <collision>
            <geometry>
                <cylinder length="0.3" radius="0.25"/>
            </geometry>
        </collision>

        <visual>
            <geometry>
                <cylinder length="0.3" radius="0.25"/>
            </geometry>
            <material name="DarkBlue">
                <color rgba="0.2 0.2 0.4 1" />
            </material>
        </visual>
    </link>

    <link name="base_footprint">
    </link>

    <joint name="joint_base_footprint" type="fixed">
        <origin rpy="0 0 0" xyz="0.0 0.0 -0.15" />
        <child link="base_footprint" />
        <parent link="base_link" />
    </joint>

    <!-- Joint - front caster wheel -->
    <joint name="joint_chassis_front_caster_wheel" type="fixed">
        <origin rpy="0 0 0" xyz="0.1 0.0 -0.15" />
        <child link="link_front_caster_wheel" />
        <parent link="base_link" />
        <joint_properties damping="1.0" friction="0.0" />
    </joint>
    <!-- Link - front caster wheel -->
    <link name="link_front_caster_wheel">
        <inertial>
            <mass value="1" />
            <origin xyz="0 0 0" rpy="0 0 0" />
            <inertia ixx="0.00025" ixy="0" ixz="0" iyy="0.00025" iyz="0" izz="0.00025"/>
        </inertial>
        <!-- Caster wheel -->
        <collision>
            <origin rpy="0 0 0" xyz="0.0 0.0 0.0" />
            <geometry>
                <sphere radius="0.025" />
            </geometry>
        </collision>
        <visual>
            <origin rpy="0 0 0" xyz="0.0 0.0 0.0" />
            <geometry>
                <sphere radius="0.025" />
            </geometry>
            <material name="Grey">
                <color rgba="0.6 0.6 0.6 1" />
            </material>
        </visual>
    </link>

    <!-- Joint - back caster wheel -->
    <joint name="joint_chassis_back_caster_wheel" type="fixed">
        <origin rpy="0 0 0" xyz="-0.1 0.0 -0.15" />
        <child link="link_back_caster_wheel" />
        <parent link="base_link" />
        <joint_properties damping="1.0" friction="0.0" />
    </joint>
    <!-- Link - back caster wheel -->
    <link name="link_back_caster_wheel">
        <inertial>
            <mass value="1" />
            <origin xyz="0 0 0" rpy="0 0 0" />
            <inertia ixx="0.00025" ixy="0" ixz="0" iyy="0.00025" iyz="0" izz="0.00025"/>
        </inertial>
        <collision>
            <origin rpy="0 0 0" xyz="0.0 0.0 0.0" />
            <geometry>
                <sphere radius="0.025" />
            </geometry>
        </collision>
        <visual>
            <origin rpy="0 0 0" xyz="0.0 0.0 0.0" />
            <geometry>
                <sphere radius="0.025" />
            </geometry>
            <material name="Grey">
                <color rgba="0.6 0.6 0.6 1" />
            </material>
        </visual>
    </link>

    <!-- Joint - chassis / left wheel -->
    <joint name="joint_chassis_left_wheel" type="continuous">
        <origin rpy="0 0 0" xyz="0 -0.2 -0.15" />
        <child link="link_left_wheel" />
        <parent link="base_link" />
        <axis rpy="0 0 0" xyz="0 1 0" />
        <limit effort="10000" velocity="1000" />
        <joint_properties damping="1.0" friction="1.0" />
    </joint>
    <!-- Link - left wheel -->
    <link name="link_left_wheel">
        <inertial>
            <mass value="1" />
            <origin xyz="0 0 0" rpy="0 0 0" />
            <inertia ixx="0.00020833" ixy="0" ixz="0" iyy="0.00020833" iyz="0" izz="0.0003125"/>
        </inertial>
        <collision>
            <origin rpy="1.5707 0 0" xyz="0.0 0.0 0.0" />
            <geometry>
                <cylinder length="0.025" radius="0.025"/>
            </geometry>
        </collision>
        <visual>
            <origin rpy="1.5707 0 0" xyz="0.0 0.0 0.0" />
            <geometry>
                <cylinder length="0.025" radius="0.025"/>
            </geometry>
            <material name="red">
                <color rgba="1 0.1 0.1 1" />
            </material>
        </visual>
    </link>

    <!-- Joint - chassis / right wheel -->
    <joint name="joint_chassis_right_wheel" type="continuous">
        <origin rpy="0 0 0" xyz="0 0.2 -0.15" />
        <child link="link_right_wheel" />
        <parent link="base_link" />
        <axis rpy="0 0 0" xyz="0 1 0" />
        <limit effort="10000" velocity="1000" />
        <joint_properties damping="1.0" friction="1.0" />
    </joint>
    <!-- Link - right wheel -->
    <link name="link_right_wheel">
        <inertial>
            <mass value="1" />
            <origin xyz="0 0 0" rpy="0 0 0" />
            <inertia ixx="0.00020833" ixy="0" ixz="0" iyy="0.00020833" iyz="0" izz="0.0003125"/>
        </inertial>
        <collision>
            <origin rpy="1.5707 0 0" xyz="0.0 0.0 0.0" />
            <geometry>
                <cylinder length="0.025" radius="0.025"/>
            </geometry>
        </collision>
        <visual>
            <origin rpy="1.5707 0 0" xyz="0.0 0.0 0.0" />
            <geometry>
                <cylinder length="0.025" radius="0.025"/>
            </geometry>
            <material name="red">
                <color rgba="1 0.1 0.1 1" />
            </material>
        </visual>
    </link>


    <!-- Gazebo tags - Laser scan -->
    <gazebo reference="joint_laser_scan_chassis">
        <preserveFixedJoint>true</preserveFixedJoint>
    </gazebo>
    <gazebo reference="front_laser">
        <material>Gazebo/DarkGrey</material>
    </gazebo>

    <!-- Laser scan -->
    <joint name="joint_laser_scan_chassis" type="fixed">
        <origin rpy="3.14 0 0" xyz="0.25 0.0 0.075" />
        <child link="front_laser" />
        <parent link="base_link" />
        <joint_properties damping="1.0" friction="1.0" />
    </joint>
    <link name="front_laser">
        <inertial>
            <origin xyz="0 0 0" rpy="0 0 0" />
            <mass value="0.5" />
            <inertia ixx="0.000252666666667" ixy="0" ixz="0" iyy="0.000252666666667" iyz="0" izz="0.0005"/>
        </inertial>
        <visual>
            <origin xyz="0 0 0" rpy="0 0 0" />
            <geometry>
                <cylinder radius="0.005" length="0.0020"/>
            </geometry>
            <material name="Red">
                <color rgba="0.7 0.1 0.1 1" />
            </material>
        </visual>
        <collision>
            <origin xyz="0 0 0" rpy="0 0 0"/>
            <geometry>
                <cylinder radius="0.005" length="0.0020"/>
            </geometry>
        </collision>
    </link>

    <gazebo reference="front_laser">
        <sensor type="ray" name="head_hokuyo_sensor">
            <pose>0 0 0 0 0 0</pose>
            <visualize>true</visualize>
            <update_rate>20</update_rate>
            <ray>
                <scan>
                    <horizontal>
                        <samples>720</samples>
                        <resolution>1</resolution>
                        <min_angle>-1.570796</min_angle>
                        <max_angle>1.570796</max_angle>
                    </horizontal>
                </scan>
                <range>
                    <min>0.20</min>
                    <max>10.0</max>
                    <resolution>0.01</resolution>
                </range>
                <noise>
                    <type>gaussian</type>
                    <mean>0.0</mean>
                    <stddev>0.01</stddev>
                </noise>
            </ray>
            <plugin name="gazebo_ros_head_hokuyo_controller" filename="libgazebo_ros_laser.so">
                <topicName>/scan</topicName>
                <frameName>sensor_laser</frameName>
            </plugin>
        </sensor>
    </gazebo>

</robot>